Workbook

Sheet Sheet1
A1: OrderID | B1: Date | C1: CustomerID | D1: Product | E1: Quantity | F1: UnitPrice | G1: ShippingAddress | H1: PaymentMethod | I1: OrderStatus | J1: TrackingNumber | K1: ItemsInCart | L1: CouponCode | M1: ReferralSource | N1: TotalPrice
A2: ORD200000 | B2: 44930 | C2: C72649 | D2: Monitor | E2: 5 | F2: 570.62 | G2: 928 Main St | H2: Debit Card | I2: Shipped | J2: TRK37947903 | K2: 7 | L2: SAVE10 | M2: Instagram | N2: 2853.1
A3: ORD200001 | B3: 45527 | C3: C75739 | D3: Phone | E3: 2 | F3: 151.35 | G3: 823 Main St | H3: Online | I3: Shipped | J3: TRK91186779 | K3: 3 | L3: SAVE10 | M3: Referral | N3: 302.7
A4: ORD200002 | B4: 45349 | C4: C81728 | D4: Tablet | E4: 5 | F4: 550.68 | G4: 512 Main St | H4: Credit Card | I4: Cancelled | J4: TRK42903982 | K4: 8 | L4: FREESHIP | M4: Email | N4: 2753.4
A5: ORD200003 | B5: 45214 | C5: C33540 | D5: Chair | E5: 1 | F5: 273.19 | G5: 275 Main St | H5: Debit Card | I5: Returned | J5: TRK62788070 | K5: 5 | L5: SAVE10 | M5: Facebook | N5: 273.19
A6: ORD200004 | B6: 45785 | C6: C81840 | D6: Printer | E6: 4 | F6: 626.01 | G6: 668 Main St | H6: Online | I6: Delivered | J6: TRK29241424 | K6: 8 | L6: SAVE10 | M6: Email | N6: 2504.04
A7: ORD200005 | B7: 45222 | C7: C37249 | D7: Phone | E7: 2 | F7: 245.86 | G7: 934 Main St | H7: Credit Card | I7: Shipped | J7: TRK72976927 | K7: 4 | L7: SAVE10 | M7: Instagram | N7: 491.72
A8: ORD200006 | B8: 45825 | C8: C83492 | D8: Laptop | E8: 1 | F8: 664.42 | G8: 986 Main St | H8: Gift Card | I8: Returned | J8: TRK96417362 | K8: 6 | L8: SAVE10 | M8: Facebook | N8: 664.42
A9: ORD200007 | B9: 45058 | C9: C41460 | D9: Monitor | E9: 5 | F9: 149.55 | G9: 706 Main St | H9: Cash | I9: Shipped | J9: TRK78809193 | K9: 9 | L9: FREESHIP | M9: Facebook | N9: 747.75
A10: ORD200008 | B10: 45749 | C10: C26817 | D10: Phone | E10: 2 | F10: 134.28 | G10: 904 Main St | H10: Gift Card | I10: Cancelled | J10: TRK61042692 | K10: 2 | M10: Email | N10: 268.56
A11: ORD200009 | B11: 45251 | C11: C31946 | D11: Desk | E11: 4 | F11: 509.38 | G11: 102 Main St | H11: Credit Card | I11: Shipped | J11: TRK33478363 | K11: 6 | L11: SAVE10 | M11: Google | N11: 2037.52
A12: ORD200010 | B12: 45289 | C12: C43443 | D12: Tablet | E12: 5 | F12: 625.97 | G12: 333 Main St | H12: Credit Card | I12: Returned | J12: TRK98859248 | K12: 9 | L12: WINTER15 | M12: Instagram | N12: 3129.85
A13: ORD200011 | B13: 45339 | C13: C93861 | D13: Monitor | E13: 3 | F13: 49.14 | G13: 831 Main St | H13: Online | I13: Returned | J13: TRK48234646 | K13: 7 | L13: SAVE10 | M13: Email | N13: 147.42
A14: ORD200012 | B14: 45580 | C14: C38785 | D14: Monitor | E14: 2 | F14: 180.5 | G14: 179 Main St | H14: Debit Card | I14: Pending | J14: TRK20419991 | K14: 6 | L14: FREESHIP | M14: Referral | N14: 361
A15: ORD200013 | B15: 45168 | C15: C88348 | D15: Laptop | E15: 3 | F15: 201.49 | G15: 903 Main St | H15: Credit Card | I15: Returned | J15: TRK81913874 | K15: 4 | L15: FREESHIP | M15: Facebook | N15: 604.47
A16: ORD200014 | B16: 45012 | C16: C98474 | D16: Tablet | E16: 2 | F16: 393.33 | G16: 980 Main St | H16: Debit Card | I16: Pending | J16: TRK79186539 | K16: 3 | L16: SAVE10 | M16: Instagram | N16: 786.66
A17: ORD200015 | B17: 45124 | C17: C39416 | D17: Printer | E17: 1 | F17: 473.96 | G17: 942 Main St | H17: Cash | I17: Delivered | J17: TRK54930938 | K17: 3 | M17: Google | N17: 473.96
A18: ORD200016 | B18: 44950 | C18: C28976 | D18: Printer | E18: 2 | F18: 533.81 | G18: 914 Main St | H18: Credit Card | I18: Pending | J18: TRK13194259 | K18: 3 | L18: FREESHIP | M18: Email | N18: 1067.62
A19: ORD200017 | B19: 45353 | C19: C60672 | D19: Tablet | E19: 1 | F19: 423.4 | G19: 382 Main St | H19: Debit Card | I19: Shipped | J19: TRK11972116 | K19: 3 | M19: Referral | N19: 423.4
A20: ORD200018 | B20: 45742 | C20: C84329 | D20: Desk | E20: 1 | F20: 431.44 | G20: 891 Main St | H20: Gift Card | I20: Pending | J20: TRK65191045 | K20: 3 | L20: SAVE10 | M20: Facebook | N20: 431.44
A21: ORD200019 | B21: 44949 | C21: C14552 | D21: Monitor | E21: 5 | F21: 224 | G21: 273 Main St | H21: Cash | I21: Returned | J21: TRK59101365 | K21: 9 | L21: SAVE10 | M21: Google | N21: 1120
A22: ORD200020 | B22: 45054 | C22: C54829 | D22: Chair | E22: 5 | F22: 62.51 | G22: 587 Main St | H22: Cash | I22: Pending | J22: TRK16718651 | K22: 9 | L22: WINTER15 | M22: Instagram | N22: 312.55
A23: ORD200021 | B23: 45613 | C23: C99023 | D23: Monitor | E23: 4 | F23: 342.95 | G23: 569 Main St | H23: Cash | I23: Delivered | J23: TRK52646983 | K23: 6 | M23: Google | N23: 1371.8
A24: ORD200022 | B24: 44955 | C24: C34416 | D24: Monitor | E24: 2 | F24: 49.62 | G24: 633 Main St | H24: Online | I24: Pending | J24: TRK75937350 | K24: 2 | L24: SAVE10 | M24: Google | N24: 99.24
A25: ORD200023 | B25: 45756 | C25: C42372 | D25: Phone | E25: 4 | F25: 273.25 | G25: 755 Main St | H25: Debit Card | I25: Cancelled | J25: TRK36168083 | K25: 5 | L25: FREESHIP | M25: Referral | N25: 1093
A26: ORD200024 | B26: 45595 | C26: C17470 | D26: Laptop | E26: 2 | F26: 230.95 | G26: 956 Main St | H26: Online | I26: Delivered | J26: TRK28775057 | K26: 3 | L26: WINTER15 | M26: Referral | N26: 461.9
A27: ORD200025 | B27: 45497 | C27: C42577 | D27: Monitor | E27: 1 | F27: 399.98 | G27: 709 Main St | H27: Debit Card | I27: Delivered | J27: TRK69423327 | K27: 3 | L27: WINTER15 | M27: Email | N27: 399.98
A28: ORD200026 | B28: 45357 | C28: C21944 | D28: Laptop | E28: 5 | F28: 59.55 | G28: 296 Main St | H28: Online | I28: Delivered | J28: TRK80276812 | K28: 6 | M28: Referral | N28: 297.75
A29: ORD200027 | B29: 45344 | C29: C97593 | D29: Printer | E29: 1 | F29: 472.74 | G29: 881 Main St | H29: Online | I29: Shipped | J29: TRK89117573 | K29: 6 | L29: WINTER15 | M29: Google | N29: 472.74
A30: ORD200028 | B30: 45251 | C30: C59823 | D30: Phone | E30: 4 | F30: 160.07 | G30: 568 Main St | H30: Online | I30: Pending | J30: TRK65895539 | K30: 5 | M30: Email | N30: 640.28
A31: ORD200029 | B31: 45555 | C31: C33260 | D31: Desk | E31: 3 | F31: 423.53 | G31: 930 Main St | H31: Credit Card | I31: Delivered | J31: TRK59744090 | K31: 6 | L31: SAVE10 | M31: Referral | N31: 1270.59
A32: ORD200030 | B32: 45738 | C32: C44267 | D32: Monitor | E32: 2 | F32: 426.7 | G32: 895 Main St | H32: Online | I32: Pending | J32: TRK54751444 | K32: 5 | L32: SAVE10 | M32: Referral | N32: 853.4
A33: ORD200031 | B33: 45107 | C33: C26445 | D33: Chair | E33: 3 | F33: 500.08 | G33: 996 Main St | H33: Debit Card | I33: Returned | J33: TRK31229981 | K33: 6 | M33: Facebook | N33: 1500.24
A34: ORD200032 | B34: 45047 | C34: C12388 | D34: Tablet | E34: 5 | F34: 536.72 | G34: 830 Main St | H34: Cash | I34: Delivered | J34: TRK99261395 | K34: 10 | M34: Email | N34: 2683.6
A35: ORD200033 | B35: 45082 | C35: C52184 | D35: Chair | E35: 1 | F35: 162.77 | G35: 912 Main St | H35: Online | I35: Cancelled | J35: TRK73312471 | K35: 4 | L35: WINTER15 | M35: Facebook | N35: 162.77
A36: ORD200034 | B36: 44933 | C36: C67195 | D36: Chair | E36: 4 | F36: 576.52 | G36: 926 Main St | H36: Credit Card | I36: Pending | J36: TRK55467915 | K36: 5 | L36: WINTER15 | M36: Facebook | N36: 2306.08
A37: ORD200035 | B37: 45633 | C37: C50304 | D37: Monitor | E37: 2 | F37: 465.15 | G37: 128 Main St | H37: Online | I37: Shipped | J37: TRK46850888 | K37: 2 | L37: SAVE10 | M37: Facebook | N37: 930.3
A38: ORD200036 | B38: 45785 | C38: C59337 | D38: Laptop | E38: 2 | F38: 534.43 | G38: 465 Main St | H38: Debit Card | I38: Pending | J38: TRK50961250 | K38: 5 | M38: Facebook | N38: 1068.86
A39: ORD200037 | B39: 45579 | C39: C10054 | D39: Laptop | E39: 2 | F39: 76.74 | G39: 409 Main St | H39: Cash | I39: Returned | J39: TRK94005261 | K39: 7 | L39: SAVE10 | M39: Instagram | N39: 153.48
A40: ORD200038 | B40: 45645 | C40: C15924 | D40: Laptop | E40: 1 | F40: 245.89 | G40: 549 Main St | H40: Debit Card | I40: Delivered | J40: TRK14835975 | K40: 3 | L40: SAVE10 | M40: Google | N40: 245.89
...

Sheet Analysis
A1: 📊 ORDER DATA ANALYSIS SUMMARY
A3: KEY METRICS
A4: Total Orders | B4: 1200
A5: Total Revenue | B5: 1264762
A6: Avg Order Value | B6: 1053.97
A7: Median Order Value | B7: 823.62
A8: Avg Quantity/Order | B8: 2.95
A9: Avg Unit Price | B9: 356.41
A10: Unique Customers | B10: 1189
A11: Products Offered | B11: 7
A12: Date Range Start | B12: 44927
A13: Date Range End | B13: 45838
A15: PRODUCT ANALYSIS
A16: Product | B16: Orders | C16: Total Revenue | D16: Avg Order Value | E16: Total Qty
A17: Chair | B17: 178 | C17: 195620.11 | D17: 1098.99 | E17: 562
A18: Desk | B18: 170 | C18: 167459.93 | D18: 985.06 | E18: 508
A19: Laptop | B19: 173 | C19: 192126.56 | D19: 1110.56 | E19: 535
A20: Monitor | B20: 163 | C20: 175651.41 | D20: 1077.62 | E20: 480
A21: Phone | B21: 156 | C21: 151722.39 | D21: 972.58 | E21: 411
A22: Printer | B22: 181 | C22: 195612.61 | D22: 1080.73 | E22: 542
A23: Tablet | B23: 179 | C23: 186568.95 | D23: 1042.28 | E23: 497

Sheet Data Analysis
A1: 📊 ORDER DATA ANALYSIS SUMMARY
A3: KEY METRICS | G3: ORDER STATUS
A4: Total Orders | B4: 1200 | G4: Status | H4: Count
A5: Total Revenue | B5: 1264762 | G5: Cancelled | H5: 250
A6: Avg Order Value | B6: 1054 | G6: Returned | H6: 247
A7: Median Order Value | B7: 824 | G7: Pending | H7: 237
A8: Avg Quantity/Order | B8: 2.95 | G8: Shipped | H8: 235
A9: Avg Unit Price | B9: 356 | G9: Delivered | H9: 231
A10: Unique Customers | B10: 1189
A11: Products Offered | B11: 7 | G11: PAYMENT METHODS
A12: Date Range Start | B12: 44927 | G12: Method | H12: Count
A13: Date Range End | B13: 45838 | G13: Online | H13: 258
G14: Cash | H14: 246
A15: PRODUCT ANALYSIS | G15: Credit Card | H15: 234
A16: Product | B16: Orders | C16: Revenue | D16: Avg Value | E16: Qty | G16: Debit Card | H16: 232
A17: Chair | B17: 178 | C17: 195620 | D17: 1099 | E17: 562 | G17: Gift Card | H17: 230
A18: Desk | B18: 170 | C18: 167460 | D18: 985 | E18: 508
A19: Laptop | B19: 173 | C19: 192127 | D19: 1111 | E19: 535 | G19: REFERRAL SOURCES
A20: Monitor | B20: 163 | C20: 175651 | D20: 1078 | E20: 480 | G20: Source | H20: Count
A21: Phone | B21: 156 | C21: 151722 | D21: 973 | E21: 411 | G21: Instagram | H21: 259
A22: Printer | B22: 181 | C22: 195613 | D22: 1081 | E22: 542 | G22: Email | H22: 250
A23: Tablet | B23: 179 | C23: 186569 | D23: 1042 | E23: 497 | G23: Google | H23: 241
G24: Facebook | H24: 228
A25: YEARLY TRENDS | G25: Referral | H25: 222
A26: Year | B26: Orders | C26: Revenue | D26: Avg Value
A27: 2023 | B27: 510 | C27: 552643 | D27: 1084
A28: 2024 | B28: 459 | C28: 480236 | D28: 1046
A29: 2025 | B29: 231 | C29: 231883 | D29: 1004
A31: 📋 KEY OBSERVATIONS
A32: • TREND: Revenue declining YoY - 2023 ($553K) → 2024 ($480K) → 2025 ($232K YTD)
A33: • CONCERN: 41% of orders are Cancelled (250) or Returned (247) - needs investigation
A34: • DISTRIBUTION: Products evenly spread; Printer leads (181), Phone trails (156)
A35: • INSIGHT: 99% unique customers (1,189/1,200) = very low repeat purchase rate
A36: • TOP CHANNEL: Instagram (259) & Email (250) are best referral sources
A38: 🔍 CANCELLATION & RETURN ANALYSIS
A40: BY PRODUCT
A41: Product | B41: Total Orders | C41: Cancelled | D41: Returned | E41: Cancel+Return | F41: Cancel/Return %
A42: Chair | B42: =COUNTIF(Sheet1!D:D,A42) -> 178 | C42: =COUNTIFS(Sheet1!D:D,A42,Sheet1!I:I,"Cancelled") -> 45 | D42: =COUNTIFS(Sheet1!D:D,A42,Sheet1!I:I,"Returned") -> 28 | E42: =C42+D42 -> 73 | F42: =E42/B42 -> 0.41011236
A43: Desk | B43: =COUNTIF(Sheet1!D:D,A43) -> 170 | C43: =COUNTIFS(Sheet1!D:D,A43,Sheet1!I:I,"Cancelled") -> 35 | D43: =COUNTIFS(Sheet1!D:D,A43,Sheet1!I:I,"Returned") -> 32 | E43: =C43+D43 -> 67 | F43: =E43/B43 -> 0.39411765
A44: Laptop | B44: =COUNTIF(Sheet1!D:D,A44) -> 173 | C44: =COUNTIFS(Sheet1!D:D,A44,Sheet1!I:I,"Cancelled") -> 35 | D44: =COUNTIFS(Sheet1!D:D,A44,Sheet1!I:I,"Returned") -> 39 | E44: =C44+D44 -> 74 | F44: =E44/B44 -> 0.42774566
...

Sheet Charts
